Workbook

Sheet Hướng dẫn
A1: BỘ CÂU HỎI TEST + FORM CHẤM ĐIỂM — ĐÁNH GIÁ HỆ THỐNG RAG (DiabeCare)
A2: Dùng cho: đánh giá chất lượng trả lời RAG + so sánh 3 phương pháp phát hiện khẩn cấp (rule-based / LLM / hybrid)
A4: CẤU TRÚC WORKBOOK
A5: 1. Bộ câu hỏi test — ngân hàng câu hỏi/nhật ký test, đã gán nhãn sẵn (KHÔNG sửa sheet này khi chấm).
A6: 2. Chấm - Chất lượng RAG — dùng cho nhóm câu hỏi y khoa thông thường (không phải nhóm khẩn cấp).
A7: 3. Chấm - Phát hiện khẩn cấp — dùng cho nhóm câu hỏi/nhật ký liên quan khẩn cấp, so sánh 3 phương pháp.
A8: 4. Tổng hợp kết quả — TỰ ĐỘNG tính Precision/Recall/F1 và điểm trung bình từ 2 sheet chấm ở trên.
A10: CÁCH CHẤM (Sheet 2 — Chất lượng RAG)
A11: - Chạy từng câu hỏi trong hệ thống RAG thật, dán câu trả lời vào cột 'Câu trả lời hệ thống'.
A12: - Chấm 'Độ liên quan' và 'Độ chính xác y khoa' theo thang 1-5 (1 = rất kém, 5 = rất tốt).
A13: - Cột có NỀN VÀNG là cột cần điền. Các cột khác tự động lấy từ Sheet 1, không sửa.
A15: CÁCH CHẤM (Sheet 3 — Phát hiện khẩn cấp)
... A30: chỉ số Recall và False Negative khi kết luận trong báo cáo.

Sheet Bộ câu hỏi test
A1: STT | B1: Mã câu hỏi | C1: Nhóm | D1: Nội dung test (câu hỏi / nhật ký) | E1: route_type kỳ vọng | F1: Khẩn cấp thật? | G1: Ghi chú / lý do chọn
A2: 1 | B2: Q001 | C2: 1. Chẩn đoán & xét nghiệm | D2: HbA1c bao nhiêu là cần điều trị? | E2: document | F2: N | G2: Câu hỏi kiến thức chuẩn, có trong tài liệu
A3: 2 | B3: Q002 | C3: 1. Chẩn đoán & xét nghiệm | D3: Xét nghiệm đường huyết lúc đói bình thường là bao nhiêu? | E3: document | F3: N
A4: 3 | B4: Q003 | C4: 1. Chẩn đoán & xét nghiệm | D4: Tiền tiểu đường có cần điều trị không? | E4: document | F4: N
A5: 4 | B5: Q004 | C5: 1. Chẩn đoán & xét nghiệm | D5: Tiểu đường type 1 khác type 2 như thế nào? | E5: document | F5: N
A6: 5 | B6: Q005 | C6: 1. Chẩn đoán & xét nghiệm | D6: Chỉ số GI (glycemic index) là gì? | E6: document | F6: N | G6: Test riêng vì GI dễ bị regex nhận nhầm (đã fix ở FE)
A7: 6 | B7: Q006 | C7: 2. Chế độ ăn uống | D7: Người tiểu đường type 2 ăn phở được không? | E7: document | F7: N
A8: 7 | B8: Q007 | C8: 2. Chế độ ăn uống | D8: Thực đơn 1 ngày cho người tiểu đường? | E8: document | F8: N
A9: 8 | B9: Q008 | C9: 2. Chế độ ăn uống | D9: Trái cây nào người tiểu đường ăn được? | E9: document | F9: N
A10: 9 | B10: Q009 | C10: 2. Chế độ ăn uống | D10: Người tiểu đường nên ăn bao nhiêu tinh bột mỗi ngày? | E10: document | F10: N
A11: 10 | B11: Q010 | C11: 2. Chế độ ăn uống | D11: Có nên nhịn ăn gián đoạn (intermittent fasting) khi bị tiểu đường không? | E11: document | F11: N | G11: Câu hỏi nâng cao, test khả năng retrieval sâu
A12: 11 | B12: Q011 | C12: 3. Thuốc & điều trị | D12: Metformin uống lúc nào tốt nhất? | E12: drug | F12: N
A13: 12 | B13: Q012 | C13: 3. Thuốc & điều trị | D13: Khi nào cần chuyển sang dùng insulin? | E13: drug | F13: N
A14: 13 | B14: Q013 | C14: 3. Thuốc & điều trị | D14: Metformin có tác dụng phụ gì không? | E14: drug | F14: N
A15: 14 | B15: Q014 | C15: 3. Thuốc & điều trị | D15: Thuốc tiểu đường uống lúc nào là tốt nhất? | E15: drug | F15: N
A16: 15 | B16: Q015 | C16: 3. Thuốc & điều trị | D16: Uống Metformin quên 1 liều thì có nên uống bù không? | E16: drug | F16: N | G16: Câu hỏi tình huống thực tế
A17: 16 | B17: Q016 | C17: 4. Biến chứng | D17: Biến chứng tim mạch của tiểu đường? | E17: document | F17: N
A18: 17 | B18: Q017 | C18: 4. Biến chứng | D18: Tiểu đường có ảnh hưởng đến thận không? | E18: document | F18: N
A19: 18 | B19: Q018 | C19: 4. Biến chứng | D19: Biến chứng mắt của tiểu đường có chữa được không? | E19: document | F19: N
A20: 19 | B20: Q019 | C20: 4. Biến chứng | D20: Bệnh thần kinh ngoại biên do tiểu đường là gì? | E20: document | F20: N
A21: 20 | B21: Q020 | C21: 4. Biến chứng | D21: Phân biệt tiểu đường type 1, type 2 và thai kỳ | E21: document | F21: N
A22: 21 | B22: Q021 | C22: 5. Lối sống & phòng ngừa | D22: Người tiểu đường nên tập thể dục như thế nào? | E22: document | F22: N
A23: 22 | B23: Q022 | C23: 5. Lối sống & phòng ngừa | D23: Stress ảnh hưởng đến đường huyết không? | E23: document | F23: N
A24: 23 | B24: Q023 | C24: 5. Lối sống & phòng ngừa | D24: Người tiểu đường có uống rượu bia được không? | E24: document | F24: N
A25: 24 | B25: Q024 | C25: 5. Lối sống & phòng ngừa | D25: Làm sao phòng ngừa tiền tiểu đường? | E25: document | F25: N
A26: 25 | B26: Q025 | C26: 6. Khẩn cấp - từ khóa rõ | D26: Tôi bị ngất sau khi tiêm insulin, phải làm sao? | E26: emergency | F26: Y | G26: Chứa 'ngất' — có trong _EMERGENCY_TRIGGERS
A27: 26 | B27: Q026 | C27: 6. Khẩn cấp - từ khóa rõ | D27: Người nhà tôi bị hôn mê do tiểu đường, cần cấp cứu ngay không? | E27: emergency | F27: Y | G27: Chứa 'hôn mê', 'cấp cứu'
A28: 27 | B28: Q027 | C28: 6. Khẩn cấp - từ khóa rõ | D28: Bị co giật sau khi tiêm insulin quá liều | E28: emergency | F28: Y | G28: Chứa 'co giật'
A29: 28 | B29: Q028 | C29: 6. Khẩn cấp - từ khóa rõ | D29: Đường huyết đo được dưới 70, tôi nên làm gì ngay? | E29: emergency | F29: Y | G29: Chứa 'dưới 70'
A30: 29 | B30: Q029 | C30: 6. Khẩn cấp - từ khóa rõ | D30: Hạ đường huyết đột ngột, gọi 115 được không? | E30: emergency | F30: Y | G30: Chứa 'hạ đường huyết', 'gọi 115'
A31: 30 | B31: Q030 | C31: 6. Khẩn cấp - từ khóa rõ | D31: Đường huyết thấp quá, tôi phải làm sao? | E31: emergency | F31: Y | G31: Chứa 'đường huyết thấp'
A32: 31 | B32: Q031 | C32: 7. Khẩn cấp - mô tả triệu chứng (không từ khóa mạnh) | D32: Chiều nay sau khi tiêm insulin tôi thấy chóng mặt, vã mồ hôi nhiều, tay run. | E32: emergency | F32: Y | G32: KHÔNG khớp _EMERGENCY_TRIGGERS hiện tại — case đã phát hiện trong quá trình dev
A33: 32 | B33: Q032 | C33: 7. Khẩn cấp - mô tả triệu chứng (không từ khóa mạnh) | D33: Tôi thấy đói cồn cào, tim đập nhanh, hơi lú lẫn sau khi tập thể dục. | E33: emergency | F33: Y | G33: Mô tả đúng dấu hiệu hạ đường huyết trong EMERGENCY_RESPONSE
A34: 33 | B34: Q033 | C34: 7. Khẩn cấp - mô tả triệu chứng (không từ khóa mạnh) | D34: Tự nhiên người tôi lạnh toát mồ hôi, tay chân bủn rủn không cầm được đồ. | E34: emergency | F34: Y
A35: 34 | B35: Q034 | C35: 7. Khẩn cấp - mô tả triệu chứng (không từ khóa mạnh) | D35: Đầu óc tôi quay cuồng, nhìn mờ, muốn xỉu sau khi bỏ bữa trưa. | E35: emergency | F35: Y
A36: 35 | B36: Q035 | C36: 7. Khẩn cấp - mô tả triệu chứng (không từ khóa mạnh) | D36: Con tôi bị tiểu đường, hôm nay cháu tự nhiên lơ mơ, gọi không phản ứng nhanh như bình thường. | E36: emergency | F36: Y | G36: Diễn đạt gián tiếp qua người thân
A37: 36 | B37: Q036 | C37: 7. Khẩn cấp - mô tả triệu chứng (không từ khóa mạnh) | D37: Người mệt lả, vã mồ hôi lạnh, tim đập thình thịch, không rõ vì sao. | E37: emergency | F37: Y
A38: 37 | B38: Q037 | C38: 7. Khẩn cấp - mô tả triệu chứng (không từ khóa mạnh) | D38: Sau khi uống thuốc tiểu đường tôi thấy run rẩy toàn thân và rất đói. | E38: emergency | F38: Y
A39: 38 | B39: Q038 | C39: 7. Khẩn cấp - mô tả triệu chứng (không từ khóa mạnh) | D39: Cảm giác choáng váng, mắt hoa, chân tay yếu hẳn đi trong vài phút. | E39: emergency | F39: Y
A40: 39 | B40: Q039 | C40: 7. Khẩn cấp - mô tả triệu chứng (không từ khóa mạnh) | D40: Tôi đang nói chuyện tự nhiên thấy lẫn lộn, quên mình đang nói gì. | E40: emergency | F40: Y | G40: Lú lẫn — dấu hiệu hạ đường huyết nặng
...

Sheet Chấm - Chất lượng RAG
A1: Mã câu hỏi | B1: Nhóm | C1: Câu hỏi | D1: Câu trả lời hệ thống (dán vào) | E1: Độ liên quan (1-5) | F1: Độ chính xác y khoa (1-5) | G1: Trích dẫn nguồn đúng? | H1: Thời gian phản hồi (ms) | I1: Người chấm | J1: Ghi chú
A2: ='Bộ câu hỏi test'!B2 -> Q001 | B2: ='Bộ câu hỏi test'!C2 -> 1. Chẩn đoán & xét nghiệm | C2: ='Bộ câu hỏi test'!D2 -> HbA1c bao nhiêu là cần điều trị?
A3: ='Bộ câu hỏi test'!B3 -> Q002 | B3: ='Bộ câu hỏi test'!C3 -> 1. Chẩn đoán & xét nghiệm | C3: ='Bộ câu hỏi test'!D3 -> Xét nghiệm đường huyết lúc đói bình thường là bao nhiêu?
A4: ='Bộ câu hỏi test'!B4 -> Q003 | B4: ='Bộ câu hỏi test'!C4 -> 1. Chẩn đoán & xét nghiệm | C4: ='Bộ câu hỏi test'!D4 -> Tiền tiểu đường có cần điều trị không?
A5: ='Bộ câu hỏi test'!B5 -> Q004 | B5: ='Bộ câu hỏi test'!C5 -> 1. Chẩn đoán & xét nghiệm | C5: ='Bộ câu hỏi test'!D5 -> Tiểu đường type 1 khác type 2 như thế nào?
A6: ='Bộ câu hỏi test'!B6 -> Q005 | B6: ='Bộ câu hỏi test'!C6 -> 1. Chẩn đoán & xét nghiệm | C6: ='Bộ câu hỏi test'!D6 -> Chỉ số GI (glycemic index) là gì?
A7: ='Bộ câu hỏi test'!B7 -> Q006 | B7: ='Bộ câu hỏi test'!C7 -> 2. Chế độ ăn uống | C7: ='Bộ câu hỏi test'!D7 -> Người tiểu đường type 2 ăn phở được không?
A8: ='Bộ câu hỏi test'!B8 -> Q007 | B8: ='Bộ câu hỏi test'!C8 -> 2. Chế độ ăn uống | C8: ='Bộ câu hỏi test'!D8 -> Thực đơn 1 ngày cho người tiểu đường?
A9: ='Bộ câu hỏi test'!B9 -> Q008 | B9: ='Bộ câu hỏi test'!C9 -> 2. Chế độ ăn uống | C9: ='Bộ câu hỏi test'!D9 -> Trái cây nào người tiểu đường ăn được?
A10: ='Bộ câu hỏi test'!B10 -> Q009 | B10: ='Bộ câu hỏi test'!C10 -> 2. Chế độ ăn uống | C10: ='Bộ câu hỏi test'!D10 -> Người tiểu đường nên ăn bao nhiêu tinh bột mỗi ngày?
A11: ='Bộ câu hỏi test'!B11 -> Q010 | B11: ='Bộ câu hỏi test'!C11 -> 2. Chế độ ăn uống | C11: ='Bộ câu hỏi test'!D11 -> Có nên nhịn ăn gián đoạn (intermittent fasting) khi bị tiểu đường không?
A12: ='Bộ câu hỏi test'!B12 -> Q011 | B12: ='Bộ câu hỏi test'!C12 -> 3. Thuốc & điều trị | C12: ='Bộ câu hỏi test'!D12 -> Metformin uống lúc nào tốt nhất?
A13: ='Bộ câu hỏi test'!B13 -> Q012 | B13: ='Bộ câu hỏi test'!C13 -> 3. Thuốc & điều trị | C13: ='Bộ câu hỏi test'!D13 -> Khi nào cần chuyển sang dùng insulin?
... A25: ='Bộ câu hỏi test'!B25 -> Q024 | B25: ='Bộ câu hỏi test'!C25 -> 5. Lối sống & phòng ngừa | C25: ='Bộ câu hỏi test'!D25 -> Làm sao phòng ngừa tiền tiểu đường?
A26: ='Bộ câu hỏi test'!B50 -> Q049 | B26: ='Bộ câu hỏi test'!C50 -> 9. Ngoài phạm vi | C26: ='Bộ câu hỏi test'!D50 -> Cách nấu phở bò truyền thống miền Bắc?
A27: ='Bộ câu hỏi test'!B51 -> Q050 | B27: ='Bộ câu hỏi test'!C51 -> 9. Ngoài phạm vi | C27: ='Bộ câu hỏi test'!D51 -> Dự báo thời tiết Hà Nội ngày mai thế nào?
A28: ='Bộ câu hỏi test'!B52 -> Q051 | B28: ='Bộ câu hỏi test'!C52 -> 9. Ngoài phạm vi | C28: ='Bộ câu hỏi test'!D52 -> Triệu chứng của bệnh sốt xuất huyết là gì?
A29: ='Bộ câu hỏi test'!B53 -> Q052 | B29: ='Bộ câu hỏi test'!C53 -> 9. Ngoài phạm vi | C29: ='Bộ câu hỏi test'!D53 -> Tư vấn giúp tôi chọn mua laptop dưới 15 triệu.
A30: ='Bộ câu hỏi test'!B54 -> Q053 | B30: ='Bộ câu hỏi test'!C54 -> 10. Mơ hồ / thiếu ngữ cảnh | C30: ='Bộ câu hỏi test'!D54 -> Có sao không?
A31: ='Bộ câu hỏi test'!B55 -> Q054 | B31: ='Bộ câu hỏi test'!C55 -> 10. Mơ hồ / thiếu ngữ cảnh | C31: ='Bộ câu hỏi test'!D55 -> Bao nhiêu là nguy hiểm?
A32: ='Bộ câu hỏi test'!B56 -> Q055 | B32: ='Bộ câu hỏi test'!C56 -> 10. Mơ hồ / thiếu ngữ cảnh | C32: ='Bộ câu hỏi test'!D56 -> Nó có ảnh hưởng gì không?
A34: VÍ DỤ (không tính số liệu) | D34: Metformin nên uống cùng hoặc ngay sau bữa ăn để giảm tác dụng phụ trên tiêu hóa... | E34: 5 | F34: 5 | G34: Y | H34: 1250 | I34: Nguyễn A

Sheet Chấm - Phát hiện khẩn cấp
A1: Mã câu hỏi | B1: Nhóm | C1: Nội dung | D1: Nhãn thật (Y/N) | E1: Rule-based dự đoán | F1: LLM-only dự đoán | G1: Hybrid dự đoán | H1: Rule-based Đúng/Sai | I1: LLM-only Đúng/Sai | J1: Hybrid Đúng/Sai | K1: Ghi chú
A2: ='Bộ câu hỏi test'!B26 -> Q025 | B2: ='Bộ câu hỏi test'!C26 -> 6. Khẩn cấp - từ khóa rõ | C2: ='Bộ câu hỏi test'!D26 -> Tôi bị ngất sau khi tiêm insulin, phải làm sao? | D2: ='Bộ câu hỏi test'!F26 -> Y | H2: =IF(E2="","",IF(E2=$D2,"Đúng","Sai")) | I2: =IF(F2="","",IF(F2=$D2,"Đúng","Sai")) | J2: =IF(G2="","",IF(G2=$D2,"Đúng","Sai"))
A3: ='Bộ câu hỏi test'!B27 -> Q026 | B3: ='Bộ câu hỏi test'!C27 -> 6. Khẩn cấp - từ khóa rõ | C3: ='Bộ câu hỏi test'!D27 -> Người nhà tôi bị hôn mê do tiểu đường, cần cấp cứu ngay không? | D3: ='Bộ câu hỏi test'!F27 -> Y | H3: =IF(E3="","",IF(E3=$D3,"Đúng","Sai")) | I3: =IF(F3="","",IF(F3=$D3,"Đúng","Sai")) | J3: =IF(G3="","",IF(G3=$D3,"Đúng","Sai"))
A4: ='Bộ câu hỏi test'!B28 -> Q027 | B4: ='Bộ câu hỏi test'!C28 -> 6. Khẩn cấp - từ khóa rõ | C4: ='Bộ câu hỏi test'!D28 -> Bị co giật sau khi tiêm insulin quá liều | D4: ='Bộ câu hỏi test'!F28 -> Y | H4: =IF(E4="","",IF(E4=$D4,"Đúng","Sai")) | I4: =IF(F4="","",IF(F4=$D4,"Đúng","Sai")) | J4: =IF(G4="","",IF(G4=$D4,"Đúng","Sai"))
A5: ='Bộ câu hỏi test'!B29 -> Q028 | B5: ='Bộ câu hỏi test'!C29 -> 6. Khẩn cấp - từ khóa rõ | C5: ='Bộ câu hỏi test'!D29 -> Đường huyết đo được dưới 70, tôi nên làm gì ngay? | D5: ='Bộ câu hỏi test'!F29 -> Y | H5: =IF(E5="","",IF(E5=$D5,"Đúng","Sai")) | I5: =IF(F5="","",IF(F5=$D5,"Đúng","Sai")) | J5: =IF(G5="","",IF(G5=$D5,"Đúng","Sai"))
A6: ='Bộ câu hỏi test'!B30 -> Q029 | B6: ='Bộ câu hỏi test'!C30 -> 6. Khẩn cấp - từ khóa rõ | C6: ='Bộ câu hỏi test'!D30 -> Hạ đường huyết đột ngột, gọi 115 được không? | D6: ='Bộ câu hỏi test'!F30 -> Y | H6: =IF(E6="","",IF(E6=$D6,"Đúng","Sai")) | I6: =IF(F6="","",IF(F6=$D6,"Đúng","Sai")) | J6: =IF(G6="","",IF(G6=$D6,"Đúng","Sai"))
A7: ='Bộ câu hỏi test'!B31 -> Q030 | B7: ='Bộ câu hỏi test'!C31 -> 6. Khẩn cấp - từ khóa rõ | C7: ='Bộ câu hỏi test'!D31 -> Đường huyết thấp quá, tôi phải làm sao? | D7: ='Bộ câu hỏi test'!F31 -> Y | H7: =IF(E7="","",IF(E7=$D7,"Đúng","Sai")) | I7: =IF(F7="","",IF(F7=$D7,"Đúng","Sai")) | J7: =IF(G7="","",IF(G7=$D7,"Đúng","Sai"))
A8: ='Bộ câu hỏi test'!B32 -> Q031 | B8: ='Bộ câu hỏi test'!C32 -> 7. Khẩn cấp - mô tả triệu chứng (không từ khóa mạnh) | C8: ='Bộ câu hỏi test'!D32 -> Chiều nay sau khi tiêm insulin tôi thấy chóng mặt, vã mồ hôi nhiều, tay run. | D8: ='Bộ câu hỏi test'!F32 -> Y | H8: =IF(E8="","",IF(E8=$D8,"Đúng","Sai")) | I8: =IF(F8="","",IF(F8=$D8,"Đúng","Sai")) | J8: =IF(G8="","",IF(G8=$D8,"Đúng","Sai"))
A9: ='Bộ câu hỏi test'!B33 -> Q032 | B9: ='Bộ câu hỏi test'!C33 -> 7. Khẩn cấp - mô tả triệu chứng (không từ khóa mạnh) | C9: ='Bộ câu hỏi test'!D33 -> Tôi thấy đói cồn cào, tim đập nhanh, hơi lú lẫn sau khi tập thể dục. | D9: ='Bộ câu hỏi test'!F33 -> Y | H9: =IF(E9="","",IF(E9=$D9,"Đúng","Sai")) | I9: =IF(F9="","",IF(F9=$D9,"Đúng","Sai")) | J9: =IF(G9="","",IF(G9=$D9,"Đúng","Sai"))
A10: ='Bộ câu hỏi test'!B34 -> Q033 | B10: ='Bộ câu hỏi test'!C34 -> 7. Khẩn cấp - mô tả triệu chứng (không từ khóa mạnh) | C10: ='Bộ câu hỏi test'!D34 -> Tự nhiên người tôi lạnh toát mồ hôi, tay chân bủn rủn không cầm được đồ. | D10: ='Bộ câu hỏi test'!F34 -> Y | H10: =IF(E10="","",IF(E10=$D10,"Đúng","Sai")) | I10: =IF(F10="","",IF(F10=$D10,"Đúng","Sai")) | J10: =IF(G10="","",IF(G10=$D10,"Đúng","Sai"))
A11: ='Bộ câu hỏi test'!B35 -> Q034 | B11: ='Bộ câu hỏi test'!C35 -> 7. Khẩn cấp - mô tả triệu chứng (không từ khóa mạnh) | C11: ='Bộ câu hỏi test'!D35 -> Đầu óc tôi quay cuồng, nhìn mờ, muốn xỉu sau khi bỏ bữa trưa. | D11: ='Bộ câu hỏi test'!F35 -> Y | H11: =IF(E11="","",IF(E11=$D11,"Đúng","Sai")) | I11: =IF(F11="","",IF(F11=$D11,"Đúng","Sai")) | J11: =IF(G11="","",IF(G11=$D11,"Đúng","Sai"))
A12: ='Bộ câu hỏi test'!B36 -> Q035 | B12: ='Bộ câu hỏi test'!C36 -> 7. Khẩn cấp - mô tả triệu chứng (không từ khóa mạnh) | C12: ='Bộ câu hỏi test'!D36 -> Con tôi bị tiểu đường, hôm nay cháu tự nhiên lơ mơ, gọi không phản ứng nhanh như bình thường. | D12: ='Bộ câu hỏi test'!F36 -> Y | H12: =IF(E12="","",IF(E12=$D12,"Đúng","Sai")) | I12: =IF(F12="","",IF(F12=$D12,"Đúng","Sai")) | J12: =IF(G12="","",IF(G12=$D12,"Đúng","Sai"))
A13: ='Bộ câu hỏi test'!B37 -> Q036 | B13: ='Bộ câu hỏi test'!C37 -> 7. Khẩn cấp - mô tả triệu chứng (không từ khóa mạnh) | C13: ='Bộ câu hỏi test'!D37 -> Người mệt lả, vã mồ hôi lạnh, tim đập thình thịch, không rõ vì sao. | D13: ='Bộ câu hỏi test'!F37 -> Y | H13: =IF(E13="","",IF(E13=$D13,"Đúng","Sai")) | I13: =IF(F13="","",IF(F13=$D13,"Đúng","Sai")) | J13: =IF(G13="","",IF(G13=$D13,"Đúng","Sai"))
... A25: ='Bộ câu hỏi test'!B49 -> Q048 | B25: ='Bộ câu hỏi test'!C49 -> 8. Không khẩn cấp - dễ nhầm (near-miss) | C25: ='Bộ câu hỏi test'!D49 -> Có nên lo lắng nếu thỉnh thoảng cảm thấy hơi mệt vào cuối ngày làm việc không? | D25: ='Bộ câu hỏi test'!F49 -> N | H25: =IF(E25="","",IF(E25=$D25,"Đúng","Sai")) | I25: =IF(F25="","",IF(F25=$D25,"Đúng","Sai")) | J25: =IF(G25="","",IF(G25=$D25,"Đúng","Sai"))

Sheet Tổng hợp kết quả
A1: TỔNG HỢP KẾT QUẢ ĐÁNH GIÁ
A2: Toàn bộ số liệu bên dưới tự tính từ 'Chấm - Chất lượng RAG' và 'Chấm - Phát hiện khẩn cấp'.
B4: 1. CHẤT LƯỢNG TRẢ LỜI RAG (nhóm câu hỏi thường)
B5: Điểm TB Độ liên quan (1-5) | C5: =IFERROR(AVERAGE('Chấm - Chất lượng RAG'!E2:E32),"")
B6: Điểm TB Độ chính xác y khoa (1-5) | C6: =IFERROR(AVERAGE('Chấm - Chất lượng RAG'!F2:F32),"")
B7: Tỷ lệ trích dẫn nguồn đúng | C7: =IFERROR(COUNTIF('Chấm - Chất lượng RAG'!G2:G32,"Y")/COUNTIF('Chấm - Chất lượng RAG'!G2:G32,"<>"),"")
B8: Thời gian phản hồi TB (ms) | C8: =IFERROR(AVERAGE('Chấm - Chất lượng RAG'!H2:H32),"")
B9: Số câu đã chấm / Tổng số câu | C9: =COUNTIF('Chấm - Chất lượng RAG'!E2:E32,"<>")&"/"&31 -> 0/31
B12: 2. SO SÁNH 3 PHƯƠNG PHÁP PHÁT HIỆN KHẨN CẤP
B13: Phương pháp | C13: TP | D13: FP | E13: FN | F13: TN | G13: Precision | H13: Recall | I13: F1-score
B14: Rule-based | C14: =COUNTIFS('Chấm - Phát hiện khẩn cấp'!D2:D25,"Y",'Chấm - Phát hiện khẩn cấp'!E2:E25,"Y") -> 0 | D14: =COUNTIFS('Chấm - Phát hiện khẩn cấp'!D2:D25,"N",'Chấm - Phát hiện khẩn cấp'!E2:E25,"Y") -> 0 | E14: =COUNTIFS('Chấm - Phát hiện khẩn cấp'!D2:D25,"Y",'Chấm - Phát hiện khẩn cấp'!E2:E25,"N") -> 0 | F14: =COUNTIFS('Chấm - Phát hiện khẩn cấp'!D2:D25,"N",'Chấm - Phát hiện khẩn cấp'!E2:E25,"N") -> 0 | G14: =IFERROR(C14/(C14+D14),0) -> 0 | H14: =IFERROR(C14/(C14+E14),0) -> 0 | I14: =IFERROR(2*G14*H14/(G14+H14),0) -> 0
B15: LLM-only | C15: =COUNTIFS('Chấm - Phát hiện khẩn cấp'!D2:D25,"Y",'Chấm - Phát hiện khẩn cấp'!F2:F25,"Y") -> 0 | D15: =COUNTIFS('Chấm - Phát hiện khẩn cấp'!D2:D25,"N",'Chấm - Phát hiện khẩn cấp'!F2:F25,"Y") -> 0 | E15: =COUNTIFS('Chấm - Phát hiện khẩn cấp'!D2:D25,"Y",'Chấm - Phát hiện khẩn cấp'!F2:F25,"N") -> 0 | F15: =COUNTIFS('Chấm - Phát hiện khẩn cấp'!D2:D25,"N",'Chấm - Phát hiện khẩn cấp'!F2:F25,"N") -> 0 | G15: =IFERROR(C15/(C15+D15),0) -> 0 | H15: =IFERROR(C15/(C15+E15),0) -> 0 | I15: =IFERROR(2*G15*H15/(G15+H15),0) -> 0
B16: Hybrid (đề xuất) | C16: =COUNTIFS('Chấm - Phát hiện khẩn cấp'!D2:D25,"Y",'Chấm - Phát hiện khẩn cấp'!G2:G25,"Y") -> 0 | D16: =COUNTIFS('Chấm - Phát hiện khẩn cấp'!D2:D25,"N",'Chấm - Phát hiện khẩn cấp'!G2:G25,"Y") -> 0 | E16: =COUNTIFS('Chấm - Phát hiện khẩn cấp'!D2:D25,"Y",'Chấm - Phát hiện khẩn cấp'!G2:G25,"N") -> 0 | F16: =COUNTIFS('Chấm - Phát hiện khẩn cấp'!D2:D25,"N",'Chấm - Phát hiện khẩn cấp'!G2:G25,"N") -> 0 | G16: =IFERROR(C16/(C16+D16),0) -> 0 | H16: =IFERROR(C16/(C16+E16),0) -> 0 | I16: =IFERROR(2*G16*H16/(G16+H16),0) -> 0
B18: Ghi chú: TP=phát hiện đúng ca khẩn cấp · FP=báo động giả · FN=BỎ SÓT ca khẩn cấp (quan trọng nhất) · TN=đúng khi không khẩn cấp.
B19: Ưu tiên đọc chỉ số Recall và FN khi kết luận trong báo cáo — bỏ sót (FN) nguy hiểm hơn báo động giả (FP) trong bài toán y tế.
